Workbook

Sheet 대시보드
B2: 민엽 & 현지 자산관리 대시보드
B3: 기준일: 2026년 05월 17일 | 각 시트에 입력하면 자동 업데이트
B5: 현재 순자산
B6: 항목 | C6: 민엽 | D6: 현지 | E6: 합계
B7: 현금·예금 | C7: =자산현황!C16 -> 6513400 | D7: =자산현황!E16 -> 21489076 | E7: =자산현황!F16 -> 28002476
B8: 투자자산 | C8: =자산현황!C25 -> 274538299 | D8: =자산현황!E25 -> 127765857 | E8: =자산현황!F25 -> 402304156
B9: 계약금 | C9: =자산현황!C29 -> 130000000 | D9: =자산현황!E29 -> 0 | E9: =자산현황!F29 -> 130000000 | G9: D-Day
B10: 부채 | C10: =자산현황!C36 -> -106000000 | D10: =자산현황!E36 -> 0 | E10: =자산현황!F36 -> -106000000 | G10: 결혼식 (2027.07) | H10: 46569 | I10: =DATEDIF(TODAY(),H10,"D") -> 409
B11: 순 자 산 | C11: =자산현황!C40 -> 305051699 | D11: =자산현황!E40 -> 149254933 | E11: =자산현황!F40 -> 454306632 | G11: 잔금일 (2027.09) | H11: 46631 | I11: =DATEDIF(TODAY(),H11,"D") -> 471
B14: 2027년 자금 계획 요약
B15: 구분 | C15: 항목 | F15: 금액 (원) | G15: 비고
B16: 지출 | C16: 잔금 자기자금 | F16: =부동산계획!D7 -> 220000000
B17: 지출 | C17: 취득세·부대비용 | F17: =부동산계획!D9 -> 50000000
B18: 지출 | C18: 세입자 보증금 반환 | F18: =부동산계획!D10 -> 300000000
B19: 지출 | C19: 인테리어·가전 | F19: =부동산계획!D11 -> 50000000
B20: 지출 | C20: 결혼식·신혼여행 | F20: =결혼계획!D7 -> 50000000
B21: 지출 | C21: 어머니 차용금 상환 | F21: =106000000 -> 106000000
C22: 지출 합계 | F22: =SUM(F16,F17,F18,F19,F20,F21) -> 776000000
B23: 가용 | C23: 현재 가용 자산 (현금+투자-부채) | F23: =자산현황!F41 -> 324306632
B24: 가용 | C24: 2027.9까지 저축 예상 | F24: =월별저축!I55 -> 69500000
B25: 가용 | C25: 대출 예정 | F25: =부동산계획!D8+부동산계획!D34 -> 660000000
B26: 가용 | C26: 예상 축의금 | F26: =결혼계획!D8 -> 30000000
C27: 가용 합계 | F27: =SUM(F23,F24,F25,F26) -> 1083806632
C28: 여유 / 부족 | F28: =F27-F22 -> 307806632
B30: ※ 각 시트(부동산계획·결혼계획·자산현황·월별저축)에 값을 입력하면 자동 반영됩니다.

Sheet 자산현황
B2: 자산 현황
B3: 기준: 매월 말일 업데이트 | D=민엽, E=현지, F=합계
B4: 현금 · 예금
B5: 항 목 | C5: 민 엽 | D5: 항 목 | E5: 현 지 | F5: 합 계
B6: 토스뱅크 | C6: 1794954 | D6: OK 저축은행 | E6: 20722500 | F6: =C6+E6 -> 22517454
B7: 주택청약(→연금) | C7: 0 | D7: 주택청약(→연금) | E7: 0 | F7: =C7+E7 -> 0
B8: 하나은행 | C8: 72561 | D8: 농협 | E8: 766576 | F8: =C8+E8 -> 839137
B9: 기업은행 | C9: 109094 | D9: 기업은행 | E9: 0 | F9: =C9+E9 -> 109094
B10: 카카오뱅크 | C10: 150012 | F10: =C10+E10 -> 150012
B11: 우리은행 | C11: 50000 | F11: =C11+E11 -> 50000
B12: OK토스플러스 | C12: 300000 | F12: =C12+E12 -> 300000
B13: 지역화폐 | C13: 36779 | F13: =C13+E13 -> 36779
B14: 배터리카드 | C14: 400000 | F14: =C14+E14 -> 400000
B15: 기타 | C15: 3600000 | F15: =C15+E15 -> 3600000
B16: 소 계 | C16: =SUM(C6:C15) -> 6513400 | E16: =SUM(E6,E8,E9,E10,E11,E12,E13,E14,E15) -> 21489076 | F16: =C16+E16 -> 28002476
B17: 투자 자산 (주식 · 코인 · 연금)
B18: 항 목 | C18: 민 엽 | D18: 항 목 | E18: 현 지 | F18: 합 계
B19: 키움증권 | C19: 87576544 | D19: 한국투자증권 | E19: 76114704 | F19: =C19+E19 -> 163691248
B20: 토스주식 | C20: 99471104 | D20: 토스증권 | E20: 41075120 | F20: =C20+E20 -> 140546224
B21: 자사주 | C21: 9381394 | D21: 대신증권 | E21: 2035000 | F21: =C21+E21 -> 11416394
B22: ISA | C22: 9381394 | D22: ISA (현지) | E22: 5297783 | F22: =C22+E22 -> 14679177
B23: IRP·연금·청약 | C23: 37464836 | D23: 연금·청약(현지) | E23: 2562952 | F23: =C23+E23 -> 40027788
B24: 비트코인 | C24: 31263027 | D24: 업비트 | E24: 680298 | F24: =C24+E24 -> 31943325
B25: 소 계 | C25: =SUM(C19,C20,C21,C22,C23,C24) -> 274538299 | E25: =SUM(E19,E20,E21,E22,E23,E24) -> 127765857 | F25: =C25+E25 -> 402304156
B26: 계약금 납부 (유동성 없음)
B27: 항 목 | C27: 민 엽 | D27: 항 목 | E27: 현 지 | F27: 합 계
B28: 계약금 납부 (아파트) | C28: 130000000 | E28: 0 | F28: =C28+E28 -> 130000000 | G28: 2025.04 납부 / 잔금 전 고정
B29: 소 계 | C29: =SUM(C28) -> 130000000 | E29: =SUM(E28) -> 0 | F29: =C29+E29 -> 130000000
B30: 부 채 (마이너스 입력)
B31: 항 목 | C31: 민 엽 | D31: 항 목 | E31: 현 지 | F31: 합 계
B32: 대출(어머니) | C32: -106000000 | D32: 대출(어머니) | E32: 0 | F32: =C32+E32 -> -106000000
B33: 대출(주담대) | C33: 0 | D33: 대출(주담대) | E33: 0 | F33: =C33+E33 -> 0
B34: 대출(보증금 반환) | C34: 0 | D34: 대출(보증금 반환) | E34: 0 | F34: =C34+E34 -> 0
B35: 대출(신용) | C35: 0 | D35: 대출(신용) | E35: 0 | F35: =C35+E35 -> 0
B36: 소 계 | C36: =SUM(C32:C35) -> -106000000 | E36: =SUM(E32:E35) -> 0 | F36: =C36+E36 -> -106000000
B38: 순자산 합계
B39: 항 목 | C39: 민 엽 | D39: 항 목 | E39: 현 지 | F39: 합 계
B40: 순자산 = 현금+투자+계약금 - 부채 | C40: =C16+C25+C29+C36 -> 305051699 | D40: =D16+D25+D29+D36 -> 0 | E40: =E16+E25+E29+E36 -> 149254933 | F40: =F16+F25+F29+F36 -> 454306632
B41: 가용 자산 = 현금+투자-부채 | C41: =C16+C25+C36 -> 175051699 | D41: =D16+D25+D36 -> 0 | E41: =E16+E25+E36 -> 149254933 | F41: =C41+E41 -> 324306632
B43: ※ D·E열(금액)만 수정. F열과 소계·순자산은 자동 계산.

Sheet 자산_이력
B2: 자산 월별 이력
B3: 매월 말일 잔액을 직접 입력하세요. 순자산·전월비·변동률은 자동 계산됩니다.
B4: 월 | C4: 민 엽 | H4: 현 지 | L4: 합 계
C5: 현금·예금 | D5: 주식·코인 | E5: IRP·연금 | F5: 기타 | G5: 순자산 | H5: 현금·예금 | I5: 주식 | J5: IRP·연금 | K5: 순자산 | L5: 순자산 합계 | M5: 전월비 | N5: 변동률
B6: 46143 | C6: =자산현황!C16 -> 6513400 | D6: =SUM(자산현황!C19+자산현황!C20+자산현황!C21+자산현황!C24) -> 227692069 | E6: 21144836 | F6: 9381394 | G6: =SUM(C6:F6) -> 264731699 | H6: =자산현황!E16 -> 21489076 | I6: =자산현황!E19+자산현황!E20+자산현황!E21+자산현황!E22+자산현황!E24 -> 125202905 | J6: =자산현황!E23 -> 2562952 | K6: =SUM(H6:J6) -> 149254933 | L6: =G6+K6 -> 413986632
B7: 46174 | C7: 0 | D7: 0 | E7: 0 | F7: 0 | G7: =SUM(C7:F7) -> 0 | H7: 0 | I7: 0 | J7: 0 | K7: =SUM(H7:J7) -> 0 | L7: =G7+K7 -> 0 | M7: =L7-L6 -> -413986632 | N7: =IF(L6=0,0,(L7-L6)/ABS(L6)) -> -1
B8: 46204 | G8: =C8+D8+E8+F8 -> 0 | K8: =H8+I8+J8+K8 | L8: =G8+K8 | M8: =L8-L7 | N8: =IF(L7=0,0,(L8-L7)/ABS(L7)) -> 0
B9: 46235 | G9: =C9+D9+E9+F9 -> 0 | K9: =H9+I9+J9+K9 | L9: =G9+K9 | M9: =L9-L8 | N9: =IF(L8=0,0,(L9-L8)/ABS(L8))
B10: 46266 | G10: =C10+D10+E10+F10 -> 0 | K10: =H10+I10+J10+K10 | L10: =G10+K10 | M10: =L10-L9 | N10: =IF(L9=0,0,(L10-L9)/ABS(L9))
B11: 46296 | G11: =C11+D11+E11+F11 -> 0 | K11: =H11+I11+J11+K11 | L11: =G11+K11 | M11: =L11-L10 | N11: =IF(L10=0,0,(L11-L10)/ABS(L10))
B12: 46327 | G12: =C12+D12+E12+F12 -> 0 | K12: =H12+I12+J12+K12 | L12: =G12+K12 | M12: =L12-L11 | N12: =IF(L11=0,0,(L12-L11)/ABS(L11))
B13: 46357 | G13: =C13+D13+E13+F13 -> 0 | K13: =H13+I13+J13+K13 | L13: =G13+K13 | M13: =L13-L12 | N13: =IF(L12=0,0,(L13-L12)/ABS(L12))
B14: 46388 | G14: =C14+D14+E14+F14 -> 0 | K14: =H14+I14+J14+K14 | L14: =G14+K14 | M14: =L14-L13 | N14: =IF(L13=0,0,(L14-L13)/ABS(L13))
B15: 46419 | G15: =C15+D15+E15+F15 -> 0 | K15: =H15+I15+J15+K15 | L15: =G15+K15 | M15: =L15-L14 | N15: =IF(L14=0,0,(L15-L14)/ABS(L14))
B16: 46447 | G16: =C16+D16+E16+F16 -> 0 | K16: =H16+I16+J16+K16 | L16: =G16+K16 | M16: =L16-L15 | N16: =IF(L15=0,0,(L16-L15)/ABS(L15))
B17: 46478 | G17: =C17+D17+E17+F17 -> 0 | K17: =H17+I17+J17+K17 | L17: =G17+K17 | M17: =L17-L16 | N17: =IF(L16=0,0,(L17-L16)/ABS(L16))
B18: 46508 | G18: =C18+D18+E18+F18 -> 0 | K18: =H18+I18+J18+K18 | L18: =G18+K18 | M18: =L18-L17 | N18: =IF(L17=0,0,(L18-L17)/ABS(L17))
B19: 46539 | G19: =C19+D19+E19+F19 -> 0 | K19: =H19+I19+J19+K19 | L19: =G19+K19 | M19: =L19-L18 | N19: =IF(L18=0,0,(L19-L18)/ABS(L18))
... B37: 47088 | G37: =C37+D37+E37+F37 -> 0 | K37: =H37+I37+J37+K37 | L37: =G37+K37 | M37: =L37-L36 | N37: =IF(L36=0,0,(L37-L36)/ABS(L36))
B39: ※ C~F(민엽), H~K(현지)열에 매월 말 잔액 입력. 순자산·전월비·변동률은 자동 계산.
B40: ※ 민엽 부채(어머니 차용금 1억600만)는 순자산에서 별도 차감하세요.

Sheet 민엽_가계부
B2: 민엽 월별 지출 가계부
B3: 각 카테고리별 지출을 입력하세요. 합계는 자동 계산 → 월별저축 시트에 자동 반영됩니다.
B4: 월 | C4: 식비/외식 | D4: 교통/주유 | E4: 통신/구독 | F4: 쇼핑/의류 | G4: 여가/취미 | H4: 의료/건강 | I4: 경조사 | J4: 고정지출 | K4: 부모님/용돈 | L4: 기타 | M4: 월 합계 | N4: 메모
B5: 46143 | M5: =SUM(C5:L5) -> 0
B6: 46174 | M6: =SUM(C6:L6) -> 0
B7: 46204 | M7: =SUM(C7:L7) -> 0
B8: 46235 | M8: =SUM(C8:L8) -> 0
B9: 46266 | M9: =SUM(C9:L9) -> 0
B10: 46296 | M10: =SUM(C10:L10) -> 0
B11: 46327 | M11: =SUM(C11:L11) -> 0
B12: 46357 | M12: =SUM(C12:L12) -> 0
B13: 46388 | M13: =SUM(C13:L13) -> 0
B14: 46419 | M14: =SUM(C14:L14) -> 0
B15: 46447 | M15: =SUM(C15:L15) -> 0
B16: 46478 | M16: =SUM(C16:L16) -> 0
... B36: 47088 | M36: =SUM(C36:L36) -> 0
B38: 카테고리별 합계
B39: 전체 합계 | C39: =SUM(C5:C36) -> 0 | D39: =SUM(D5:D36) -> 0 | E39: =SUM(E5:E36) -> 0 | F39: =SUM(F5:F36) -> 0 | G39: =SUM(G5:G36) -> 0 | H39: =SUM(H5:H36) -> 0 | I39: =SUM(I5:I36) -> 0 | J39: =SUM(J5:J36) -> 0 | ... M39: =SUM(M5:M36) -> 0
B41: ※ 각 셀에 숫자만 입력. 월 합계는 자동 계산.

Sheet 현지_가계부
B2: 현지 월별 지출 가계부
B3: 각 카테고리별 지출을 입력하세요. 합계는 자동 계산 → 월별저축 시트에 자동 반영됩니다.
B4: 월 | C4: 식비/외식 | D4: 교통/주유 | E4: 통신/구독 | F4: 쇼핑/의류 | G4: 여가/취미 | H4: 의료/건강 | I4: 경조사 | J4: 고정지출 | K4: 부모님/용돈 | L4: 기타 | M4: 월 합계 | N4: 메모
B5: 46143 | M5: =SUM(C5:L5) -> 0
B6: 46174 | M6: =SUM(C6:L6) -> 0
B7: 46204 | M7: =SUM(C7:L7) -> 0
B8: 46235 | M8: =SUM(C8:L8) -> 0
B9: 46266 | M9: =SUM(C9:L9) -> 0
B10: 46296 | M10: =SUM(C10:L10) -> 0
B11: 46327 | M11: =SUM(C11:L11) -> 0
B12: 46357 | M12: =SUM(C12:L12) -> 0
B13: 46388 | M13: =SUM(C13:L13) -> 0
B14: 46419 | M14: =SUM(C14:L14) -> 0
B15: 46447 | M15: =SUM(C15:L15) -> 0
B16: 46478 | M16: =SUM(C16:L16) -> 0
... B36: 47088 | M36: =SUM(C36:L36) -> 0
B38: 카테고리별 합계
B39: 전체 합계 | C39: =SUM(C5:C36) -> 0 | D39: =SUM(D5:D36) -> 0 | E39: =SUM(E5:E36) -> 0 | F39: =SUM(F5:F36) -> 0 | G39: =SUM(G5:G36) -> 0 | H39: =SUM(H5:H36) -> 0 | I39: =SUM(I5:I36) -> 0 | J39: =SUM(J5:J36) -> 0 | ... M39: =SUM(M5:M36) -> 0
B41: ※ 각 셀에 숫자만 입력. 월 합계는 자동 계산.

Sheet 월별저축
B2: 월별 저축 추이
B3: 수입만 입력하세요. 지출은 가계부 시트에서 자동 반영됩니다.
B4: 시작 순자산 (2026년 5월)
B5: 시작 순자산 | C5: 450986632 | E5: 자산현황 시트 순자산 값 입력
B7: 주요 이벤트 (해당 월 자동 차감)
B8: 연-월 | C8: 이벤트명 | F8: 금액 (원) | G8: 비고
B9: 46631 | C9: 부동산 잔금 (자기자금) | F9: -220000000
B10: 46631 | C10: 취득세·부대비용 | F10: -50000000
B11: 46569 | C11: 결혼식 비용 | F11: -50000000
B12: 46569 | C12: 신혼여행 | F12: -10000000
B13: 46600 | C13: 인테리어·가전가구 | F13: -50000000
B14: 46600 | C14: 세입자 보증금 반환 | F14: -300000000 | G14: 보증금 반환 대출 1억 추가
B19: 월별 기록
B20: 월 | C20: 민엽 수입 | D20: 현지 수입 | E20: 합계 수입 | F20: 민엽 지출 | G20: 현지 지출 | H20: 합계 지출 | I20: 저축액 | J20: 저축률 | K20: 비고
B21: 46143 | C21: 6000000 | D21: 3500000 | E21: =C21+D21 -> 9500000 | F21: 2500000 | G21: 2000000 | H21: =SUM(F21:G21) -> 4500000 | I21: =E21-H21 -> 5000000 | J21: =IF(E21=0,0,I21/E21) -> 0.52631579 | K21: 어머니 50
B22: 46174 | C22: 6000000 | D22: 3500000 | E22: =C22+D22 -> 9500000 | F22: 2500000 | G22: 2000000 | H22: =SUM(F22:G22) -> 4500000 | I22: =E22-H22 -> 5000000 | J22: =IF(E22=0,0,I22/E22) -> 0.52631579 | K22: 어머니 50
B23: 46204 | C23: 6000000 | D23: 3500000 | E23: =C23+D23 -> 9500000 | F23: 2000000 | G23: 2000000 | H23: =SUM(F23:G23) -> 4000000 | I23: =E23-H23 -> 5500000 | J23: =IF(E23=0,0,I23/E23) -> 0.57894737 | K23: 어머니 50
B24: 46235 | C24: 6000000 | D24: 5500000 | E24: =C24+D24 -> 11500000 | F24: 4000000 | G24: 2000000 | H24: =SUM(F24:G24) -> 6000000 | I24: =E24-H24 -> 5500000 | J24: =IF(E24=0,0,I24/E24) -> 0.47826087 | K24: 어머니 50 + 대출이자 150
B25: 46266 | C25: 6000000 | D25: 3500000 | E25: =C25+D25 -> 9500000 | F25: 4000000 | G25: 2000000 | H25: =SUM(F25:G25) -> 6000000 | I25: =E25-H25 -> 3500000 | J25: =IF(E25=0,0,I25/E25) -> 0.36842105 | K25: 어머니 50 + 대출이자 150
B26: 46296 | C26: 6000000 | D26: 3500000 | E26: =C26+D26 -> 9500000 | F26: 4000000 | G26: 2000000 | H26: =SUM(F26:G26) -> 6000000 | I26: =E26-H26 -> 3500000 | J26: =IF(E26=0,0,I26/E26) -> 0.36842105 | K26: 어머니 50 + 대출이자 150
B27: 46327 | C27: 6000000 | D27: 3500000 | E27: =C27+D27 -> 9500000 | F27: 4000000 | G27: 2000000 | H27: =SUM(F27:G27) -> 6000000 | I27: =E27-H27 -> 3500000 | J27: =IF(E27=0,0,I27/E27) -> 0.36842105 | K27: 어머니 50 + 대출이자 150
B28: 46357 | C28: 6000000 | D28: 3500000 | E28: =C28+D28 -> 9500000 | F28: 4000000 | G28: 2000000 | H28: =SUM(F28:G28) -> 6000000 | I28: =E28-H28 -> 3500000 | J28: =IF(E28=0,0,I28/E28) -> 0.36842105 | K28: 어머니 50 + 대출이자 150
B29: 46388 | C29: 16000000 | D29: 3500000 | E29: =C29+D29 -> 19500000 | F29: 4000000 | G29: 2000000 | H29: =SUM(F29:G29) -> 6000000 | I29: =E29-H29 -> 13500000 | J29: =IF(E29=0,0,I29/E29) -> 0.69230769 | K29: 어머니 50 + 대출이자 150
B30: 46419 | C30: 6000000 | D30: 3500000 | E30: =C30+D30 -> 9500000 | F30: 4000000 | G30: 2000000 | H30: =SUM(F30:G30) -> 6000000 | I30: =E30-H30 -> 3500000 | J30: =IF(E30=0,0,I30/E30) -> 0.36842105 | K30: 어머니 50 + 대출이자 150
B31: 46447 | C31: 6000000 | D31: 3500000 | E31: =C31+D31 -> 9500000 | F31: 4000000 | G31: 2000000 | H31: =SUM(F31:G31) -> 6000000 | I31: =E31-H31 -> 3500000 | J31: =IF(E31=0,0,I31/E31) -> 0.36842105 | K31: 어머니 50 + 대출이자 150
B32: 46478 | C32: 6000000 | D32: 3500000 | E32: =C32+D32 -> 9500000 | F32: 4000000 | G32: 2000000 | H32: =SUM(F32:G32) -> 6000000 | I32: =E32-H32 -> 3500000 | J32: =IF(E32=0,0,I32/E32) -> 0.36842105 | K32: 어머니 50 + 대출이자 150
... B35: 46569 | C35: 6000000 | D35: 3500000 | E35: =C35+D35 -> 9500000 | F35: 4000000 | G35: 2000000 | H35: =SUM(F35:G35) -> 6000000 | I35: =E35-H35 -> 3500000 | J35: =IF(E35=0,0,I35/E35) -> 0.36842105 | K35: 어머니 50 + 대출이자 150
B36: 46600
B37: 46631
B38: 46661
B39: 46692
B40: 46722
B41: 46753
B42: 46784
B43: 46813
B44: 46844
B45: 46874
B46: 46905
B47: 46935
... B52: 47088
...

Sheet 부동산계획
B2: 부동산 계획
B3: 노란색 셀에 값을 입력하세요.
B4: 핵심 요약 (자동 계산)
B5: 매매가 | D5: 1210000000
B6: 계약금 납부 | D6: 130000000
B7: 잔금 자기자금 | D7: 220000000
B8: 대출 예정 | D8: 560000000
B9: 취득세 합계 | D9: =D52 -> 50000000
B10: 세입자 보증금 | D10: 300000000
B11: 인테리어 합계 | D11: =D72 -> 50000000
B13: ① 자금 조달 계획
B14: 항 목 | D14: 금 액 | E14: 비 고
B15: 계약금 납부 (완료) | D15: 130000000 | E15: 2025.04 납부
B16: 잔금 자기자금 | D16: 220000000
B17: 대출 예정금액(주택담보) | D17: 560000000 | E17: LTV 확정 후 수정
B18: 기타 (부모님 지원 등) | D18: 0
B19: 세입자 보증금 | D19: 200000000
B20: 대출 예정금액(보증금반환) | D20: 100000000
B21: 합 계 | D21: =SUM(D15,D16,D17,D18,D19,D20) -> 1210000000
B23: ② 대출 상세
B24: 대출 종류 | D24: 560000000 | E24: 주택담보대출
B25: 대출 금액 (원)
B26: 연 금리 (%)
B27: 대출 기간 (년)
B28: 거치 기간 (년)
B29: 월 상환액 (원) | E29: 은행 계산기 확인
B30: 실행 예정일
B31: 만기일
B33: ② 대출 상세
B34: 대출 종류 | D34: 100000000 | E34: 세입자 반환금 대출
B35: 대출 금액 (원)
B36: 연 금리 (%)
B37: 대출 기간 (년)
B38: 거치 기간 (년)
B39: 월 상환액 (원) | E39: 은행 계산기 확인
B40: 실행 예정일
B41: 만기일
B43: ③ 취득세 · 부대비용 (임시)
B44: 항 목 | D44: 예산 | E44: 실제 | F44: 비고
B45: 취득세 | D45: 40000000
...

Sheet 결혼계획
B2: 결혼 계획
B3: 결혼식: 2027년 7월 | 신혼여행: 2027년 9월
B4: 핵심 요약 (자동 계산)
B5: 결혼식 합계 | D5: =D33 -> 50000000
B6: 신혼여행 합계 | D6: =D42 -> 0
B7: 결혼 총비용 | D7: =D33+D42 -> 50000000
B8: 예상 축의금 | D8: =G50 -> 30000000
B9: 결혼 순비용 | D9: =D7-D8 -> 20000000
B11: ① 결혼식 세부 예산
B12: 항 목 | D12: 예산 (원) | E12: 실제 (원) | F12: 차 액 | G12: 비 고
B13: 스튜디오 (사진촬영) | F13: =E13-D13 -> 0
B14: 드레스 | F14: =E14-D14 -> 0
B15: 메이크업 (헤어포함) | F15: =E15-D15 -> 0
B16: 신랑 예복 | F16: =E16-D16 -> 0
B17: 부케·부토니에 | F17: =E17-D17 -> 0
B18: [스드메] 소계 | D18: =SUM(D13,D14,D15,D16,D17) -> 0 | E18: =SUM(E13,E14,E15,E16,E17) -> 0 | F18: =E18-D18 -> 0
B19: 예식장 대관료 | D19: 50000000 | F19: =E19-D19 -> -50000000
B20: 뷔페·식사 | F20: =E20-D20 -> 0
B21: 웨딩케이크 | F21: =E21-D21 -> 0
B22: 사회자 | F22: =E22-D22 -> 0
B23: 영상촬영 | F23: =E23-D23 -> 0
B24: 청첩장·답례품 | F24: =E24-D24 -> 0
B25: [예식장] 소계 | D25: =SUM(D19,D20,D21,D22,D23,D24) -> 50000000 | E25: =SUM(E19,E20,E21,E22,E23,E24) -> 0 | F25: =E25-D25 -> -50000000
B26: 예물 (반지 등) | F26: =E26-D26 -> 0
B27: 예단 비용 | F27: =E27-D27 -> 0
B28: [예물·예단] 소계 | D28: =SUM(D26,D27) -> 0 | E28: =SUM(E26,E27) -> 0 | F28: =E28-D28 -> 0
B29: 기타 ① | F29: =E29-D29 -> 0
B30: 기타 ② | F30: =E30-D30 -> 0
B31: [기타] 소계 | D31: =SUM(D29,D30) -> 0 | E31: =SUM(E29,E30) -> 0 | F31: =E31-D31 -> 0
B33: 결혼식 합계 | D33: =SUM(D13,D14,D15,D16,D17,D19,D20,D21,D22,D23,D24,D26,D27,D29,D30) -> 50000000 | E33: =SUM(E13,E14,E15,E16,E17,E19,E20,E21,E22,E23,E24,E26,E27,E29,E30) -> 0 | F33: =E33-D33 -> -50000000
B35: ② 신혼여행
B36: 항 목 | D36: 예산 | E36: 실제 | F36: 차 액 | G36: 비 고
B37: 항공권 (2인) | F37: =E37-D37 -> 0
B38: 숙박 | F38: =E38-D38 -> 0
B39: 투어·액티비티 | F39: =E39-D39 -> 0
B40: 식비·쇼핑 | F40: =E40-D40 -> 0
B41: 기타 | F41: =E41-D41 -> 0
B42: 신혼여행 합계 | D42: =SUM(D37,D38,D39,D40,D41) -> 0 | E42: =SUM(E37,E38,E39,E40,E41) -> 0 | F42: =E42-D42 -> 0
B44: ③ 축의금 시뮬레이터
B45: 하객 구분 | D45: 민엽 인원 | E45: 현지 인원 | F45: 평균 축의금 | G45: 예상 수입
...
